<?xml version="1.0" ?>
<robot name="robot_car">

  <material name="silver">
    <color rgba="0.700 0.700 0.700 1.000"/>
  </material>

  <material name="black">
    <color rgba="0.000 0.000 0.000 1.000"/>
  </material>

  <link name="chassis_link">
    <inertial>
      <origin xyz="-4.786598019970162e-05 0.0006131911133205515 0.03670941891385957" rpy="0 0 0"/>
      <mass value="0.3045330924390322"/>
      <inertia ixx="0.0004677149248189586" iyy="0.0012268084504267497" izz="0.0015833986533821045" ixy="-2.7873276331366915e-08" iyz="-6.231723520375311e-08" ixz="-5.545915755561413e-08"/>
    </inertial>
    <visual>
      <origin xyz="0 0 0" rpy="0 0 0"/>
      <geometry>
        <mesh filename="meshes/chassis_link.stl" scale="0.001 0.001 0.001"/>
      </geometry>
      <material name="silver"/>
      <material/>
    </visual>
    <collision>
      <origin xyz="0 0 0" rpy="0 0 0"/>
      <geometry>
        <mesh filename="meshes/chassis_link.stl" scale="0.001 0.001 0.001"/>
      </geometry>
    </collision>
  </link>

  <link name="rf_wheel">
    <inertial>
      <origin xyz="4.296685228097341e-07 -0.018126651659136045 -1.2603823942858305e-08" rpy="0 0 0"/>
      <mass value="0.01990439861954628"/>
      <inertia ixx="8.030487421794417e-06" iyy="1.3496822794910893e-05" izz="8.03006994704836e-06" ixy="-1.589043675288837e-12" iyz="3.741947276667511e-13" ixz="-1.0036127582203208e-11"/>
    </inertial>
    <visual>
      <origin xyz="-0.057958 0.047374 -0.0345" rpy="0 0 0"/>
      <geometry>
        <mesh filename="meshes/rf_wheel.stl" scale="0.001 0.001 0.001"/>
      </geometry>
      <material name="black"/>
      <material/>
    </visual>
    <collision>
      <origin xyz="-0.057958 0.047374 -0.0345" rpy="0 0 0"/>
      <geometry>
        <mesh filename="meshes/rf_wheel.stl" scale="0.001 0.001 0.001"/>
      </geometry>
    </collision>
  </link>

  <link name="rr_wheel">
    <inertial>
      <origin xyz="4.226571092350029e-07 -0.01812665165913621 -1.2603823894286048e-08" rpy="0 0 0"/>
      <mass value="0.01990439861954628"/>
      <inertia ixx="8.03048742179443e-06" iyy="1.3496822794910906e-05" izz="8.030069947048387e-06" ixy="-1.5890436617363099e-12" iyz="3.741947276667511e-13" ixz="-1.0036127582203208e-11"/>
    </inertial>
    <visual>
      <origin xyz="0.05831 0.047374 -0.0345" rpy="0 0 0"/>
      <geometry>
        <mesh filename="meshes/rr_wheel.stl" scale="0.001 0.001 0.001"/>
      </geometry>
      <material name="black"/>
      <material/>
    </visual>
    <collision>
      <origin xyz="0.05831 0.047374 -0.0345" rpy="0 0 0"/>
      <geometry>
        <mesh filename="meshes/rr_wheel.stl" scale="0.001 0.001 0.001"/>
      </geometry>
    </collision>
  </link>

  <link name="lf_wheel">
    <inertial>
      <origin xyz="4.2713937836030835e-07 0.0181276185108565 1.1977975153398823e-08" rpy="0 0 0"/>
      <mass value="0.01990439861954628"/>
      <inertia ixx="8.030487421794417e-06" iyy="1.3496822794910906e-05" izz="8.030069947048414e-06" ixy="1.5890436346312556e-12" iyz="3.741947208904875e-13" ixz="1.0036127582203208e-11"/>
    </inertial>
    <visual>
      <origin xyz="-0.057962 -0.048949 -0.0345" rpy="0 0 0"/>
      <geometry>
        <mesh filename="meshes/lf_wheel.stl" scale="0.001 0.001 0.001"/>
      </geometry>
      <material name="black"/>
      <material/>
    </visual>
    <collision>
      <origin xyz="-0.057962 -0.048949 -0.0345" rpy="0 0 0"/>
      <geometry>
        <mesh filename="meshes/lf_wheel.stl" scale="0.001 0.001 0.001"/>
      </geometry>
    </collision>
  </link>

  <link name="lr_wheel">
    <inertial>
      <origin xyz="4.2265710906153053e-07 0.01812761851085625 1.1977975167276611e-08" rpy="0 0 0"/>
      <mass value="0.01990439861954628"/>
      <inertia ixx="8.030487421794376e-06" iyy="1.3496822794910934e-05" izz="8.030069947048332e-06" ixy="1.589043675288837e-12" iyz="3.7419473444301465e-13" ixz="1.0036127588979472e-11"/>
    </inertial>
    <visual>
      <origin xyz="0.05831 -0.048949 -0.0345" rpy="0 0 0"/>
      <geometry>
        <mesh filename="meshes/lr_wheel.stl" scale="0.001 0.001 0.001"/>
      </geometry>
      <material name="black"/>
      <material/>
    </visual>
    <collision>
      <origin xyz="0.05831 -0.048949 -0.0345" rpy="0 0 0"/>
      <geometry>
        <mesh filename="meshes/lr_wheel.stl" scale="0.001 0.001 0.001"/>
      </geometry>
    </collision>
  </link>

  <joint name="rfw_to_ch_joint" type="continuous">
    <origin xyz="0.057958 -0.047374 0.0345" rpy="0 0 0"/>
    <parent link="chassis_link"/>
    <child link="rf_wheel"/>
    <axis xyz="-0.0 1.0 0.0"/>
  </joint>
  <transmission name="rfw_to_ch_joint_tran">
    <type>transmission_interface/SimpleTransmission</type>
    <joint name="rfw_to_ch_joint">
      <hardwareInterface>PositionJointInterface</hardwareInterface>
    </joint>
    <actuator name="rfw_to_ch_joint_actr">
      <hardwareInterface>PositionJointInterface</hardwareInterface>
      <mechanicalReduction>1</mechanicalReduction>
    </actuator>
  </transmission>

  <joint name="rrw_to_ch_joint" type="continuous">
    <origin xyz="-0.05831 -0.047374 0.0345" rpy="0 0 0"/>
    <parent link="chassis_link"/>
    <child link="rr_wheel"/>
    <axis xyz="-0.0 1.0 -0.0"/>
  </joint>
  <transmission name="rrw_to_ch_joint_tran">
    <type>transmission_interface/SimpleTransmission</type>
    <joint name="rrw_to_ch_joint">
      <hardwareInterface>PositionJointInterface</hardwareInterface>
    </joint>
    <actuator name="rrw_to_ch_joint_actr">
      <hardwareInterface>PositionJointInterface</hardwareInterface>
      <mechanicalReduction>1</mechanicalReduction>
    </actuator>
  </transmission>

  <joint name="lfw_to_ch_joint" type="continuous">
    <origin xyz="0.057962 0.048949 0.0345" rpy="0 0 0"/>
    <parent link="chassis_link"/>
    <child link="lf_wheel"/>
    <axis xyz="0.0 -1.0 0.0"/>
  </joint>
  <transmission name="lfw_to_ch_joint_tran">
    <type>transmission_interface/SimpleTransmission</type>
    <joint name="lfw_to_ch_joint">
      <hardwareInterface>PositionJointInterface</hardwareInterface>
    </joint>
    <actuator name="lfw_to_ch_joint_actr">
      <hardwareInterface>PositionJointInterface</hardwareInterface>
      <mechanicalReduction>1</mechanicalReduction>
    </actuator>
  </transmission>

  <joint name="lrw_to_ch_joint" type="continuous">
    <origin xyz="-0.05831 0.048949 0.0345" rpy="0 0 0"/>
    <parent link="chassis_link"/>
    <child link="lr_wheel"/>
    <axis xyz="0.0 -1.0 -0.0"/>
  </joint>
  <transmission name="lrw_to_ch_joint_tran">
    <type>transmission_interface/SimpleTransmission</type>
    <joint name="lrw_to_ch_joint">
      <hardwareInterface>PositionJointInterface</hardwareInterface>
    </joint>
    <actuator name="lrw_to_ch_joint_actr">
      <hardwareInterface>PositionJointInterface</hardwareInterface>
      <mechanicalReduction>1</mechanicalReduction>
    </actuator>
  </transmission>

</robot>